Workbook

Sheet LEGENDA

Sheet Plan1
A1: Etabs | B1: TQS
A2: Story | B2: Story
A3: Story1 | B3: 1
A4: Story1 | B4: 2
A5: Story1 | B5: 3
A6: Story1 | B6: 4
A7: Story1 | B7: 5
A8: Story2 | B8: 6
A9: Story3 | B9: 7
A10: Story4 | B10: 8
A11: Story5 | B11: 9
A12: Story6 | B12: 10
... A54: Story50-AC | B54: 52

Sheet Pier Forces discr.
A1: TABLE: Pier Forces
A2: Story | B2: Story | C2: Pier | D2: Output Case | E2: Case Type | F2: Location | G2: P | H2: V2 | I2: V3 | J2: T | K2: M2 | L2: M3
A3: ETABS | B3: TQS | G3: tonf | H3: tonf | I3: tonf | J3: tonf-m | K3: tonf-m | L3: tonf-m
A4: Story50-AC | B4: =VLOOKUP(A4,Plan1!$A$3:$B$65,2,FALSE) -> 52 | C4: P8-1 | D4: ULS-NBR-1 | E4: Combination | F4: Top | G4: -9.8643 | H4: -1.2495 | I4: 1.6899 | J4: 0.3353 | K4: 0.0208 | L4: -0.0743
A5: Story50-AC | B5: =VLOOKUP(A5,Plan1!$A$3:$B$65,2,FALSE) -> 52 | C5: P8-1 | D5: ULS-NBR-1 | E5: Combination | F5: Bottom | G5: -33.6432 | H5: -12.3595 | I5: 2.8879 | J5: 5.7278 | K5: 6.8603 | L5: -56.77
A6: Story50-AC | B6: =VLOOKUP(A6,Plan1!$A$3:$B$65,2,FALSE) -> 52 | C6: P8-1 | D6: ULS-NBR-1 | E6: Combination | F6: Top | G6: -19.0604 | H6: -25.6083 | I6: 0.4505 | J6: -2.1141 | K6: -0.0667 | L6: -26.5022
A7: Story50-AC | B7: =VLOOKUP(A7,Plan1!$A$3:$B$65,2,FALSE) -> 52 | C7: P8-1 | D7: ULS-NBR-1 | E7: Combination | F7: Bottom | G7: -90.3936 | H7: -25.2258 | I7: 0.7639 | J7: 1.1903 | K7: 1.8465 | L7: -145.8624
A8: Story50-AC | B8: =VLOOKUP(A8,Plan1!$A$3:$B$65,2,FALSE) -> 52 | C8: P8-1 | D8: ULS-NBR-2 | E8: Combination | F8: Top | G8: -4.5773 | H8: 5.1888 | I8: 1.338 | J8: 0.6423 | K8: 0.0275 | L8: 5.4963
A9: Story50-AC | B9: =VLOOKUP(A9,Plan1!$A$3:$B$65,2,FALSE) -> 52 | C9: P8-1 | D9: ULS-NBR-2 | E9: Combination | F9: Bottom | G9: -12.47 | H9: -3.893 | I9: 2.2141 | J9: 4.3648 | K9: 5.3922 | L9: -12.7117
A10: Story50-AC | B10: =VLOOKUP(A10,Plan1!$A$3:$B$65,2,FALSE) -> 52 | C10: P8-1 | D10: ULS-NBR-2 | E10: Combination | F10: Top | G10: -13.7735 | H10: -19.17 | I10: 0.0986 | J10: -1.8071 | K10: -0.0601 | L10: -20.9316
A11: Story50-AC | B11: =VLOOKUP(A11,Plan1!$A$3:$B$65,2,FALSE) -> 52 | C11: P8-1 | D11: ULS-NBR-2 | E11: Combination | F11: Bottom | G11: -69.2205 | H11: -16.7593 | I11: 0.0901 | J11: -0.1727 | K11: 0.3783 | L11: -101.8041
A12: Story50-AC | B12: =VLOOKUP(A12,Plan1!$A$3:$B$65,2,FALSE) -> 52 | C12: P8-1 | D12: ULS-NBR-3 | E12: Combination | F12: Top | G12: -13.3203 | H12: -9.7633 | I12: 1.5066 | J12: -0.2286 | K12: 0.0032 | L12: -7.8435
A13: Story50-AC | B13: =VLOOKUP(A13,Plan1!$A$3:$B$65,2,FALSE) -> 52 | C13: P8-1 | D13: ULS-NBR-3 | E13: Combination | F13: Bottom | G13: -49.8282 | H13: -19.2686 | I13: 2.6761 | J13: 5.3449 | K13: 6.1717 | L13: -95.7436
A14: Story50-AC | B14: =VLOOKUP(A14,Plan1!$A$3:$B$65,2,FALSE) -> 52 | C14: P8-1 | D14: ULS-NBR-3 | E14: Combination | F14: Top | G14: -18.838 | H14: -24.3786 | I14: 0.7629 | J14: -1.6983 | K14: -0.0493 | L14: -23.7002
A15: Story50-AC | B15: =VLOOKUP(A15,Plan1!$A$3:$B$65,2,FALSE) -> 52 | C15: P8-1 | D15: ULS-NBR-3 | E15: Combination | F15: Bottom | G15: -83.8785 | H15: -26.9884 | I15: 1.4017 | J15: 2.6224 | K15: 3.1633 | L15: -149.1991
... A12967: Story2 | B12967: =VLOOKUP(A12967,Plan1!$A$3:$B$65,2,FALSE) -> 6 | C12967: P19-3 | D12967: ULS-NBR-4 | E12967: Combination | F12967: Bottom | G12967: -672.4851 | H12967: -2.8643 | I12967: -4.9369 | J12967: -5.0161 | K12967: -5.7483 | L12967: 17.8138
A12968: Story1 | B12968: 2 | C12968: P101-1 | D12968: ULS-NBR-1 | E12968: Combination | F12968: Top | G12968: -156.224 | H12968: 20.9694 | I12968: 3.2416 | J12968: -11.209 | K12968: -6.9362 | L12968: 183.9288
A12969: Story1 | B12969: 2 | C12969: P101-1 | D12969: ULS-NBR-1 | E12969: Combination | F12969: Bottom | G12969: -139.6804 | H12969: 83.9358 | I12969: 5.8963 | J12969: -0.6441 | K12969: -2.4998 | L12969: -121.7482
A12970: Story1 | B12970: 2 | C12970: P101-1 | D12970: ULS-NBR-1 | E12970: Combination | F12970: Top | G12970: -883.6352 | H12970: 10.6685 | I12970: 0.6682 | J12970: -17.4439 | K12970: -8.7088 | L12970: -129.8593
A12971: Story1 | B12971: 2 | C12971: P101-1 | D12971: ULS-NBR-1 | E12971: Combination | F12971: Bottom | G12971: -791.5084 | H12971: 24.9661 | I12971: 0.495 | J12971: -8.5442 | K12971: -6.616 | L12971: -186.434
A12972: Story1 | B12972: 2 | C12972: P101-1 | D12972: ULS-NBR-2 | E12972: Combination | F12972: Top | G12972: 14.9085 | H12972: 17.218 | I12972: -0.8946 | J12972: -2.6091 | K12972: -1.5412 | L12972: 180.1874
A12973: Story1 | B12973: 2 | C12973: P101-1 | D12973: ULS-NBR-2 | E12973: Combination | F12973: Bottom | G12973: 12.3866 | H12973: 67.3732 | I12973: 1.4739 | J12973: 3.7028 | K12973: -2.4054 | L12973: -65.1255
A12974: Story1 | B12974: 2 | C12974: P101-1 | D12974: ULS-NBR-2 | E12974: Combination | F12974: Top | G12974: -712.5027 | H12974: 6.9171 | I12974: -3.4681 | J12974: -8.844 | K12974: -3.3138 | L12974: -133.6007
A12975: Story1 | B12975: 2 | C12975: P101-1 | D12975: ULS-NBR-2 | E12975: Combination | F12975: Bottom | G12975: -639.4414 | H12975: 8.4035 | I12975: -3.9274 | J12975: -4.1972 | K12975: -6.5215 | L12975: -129.8114
A12976: Story1 | B12976: 2 | C12976: P101-1 | D12976: ULS-NBR-3 | E12976: Combination | F12976: Top | G12976: -333.3199 | H12976: 17.8335 | I12976: 7.7356 | J12976: -18.7654 | K12976: -11.7147 | L12976: 115.5952
A12977: Story1 | B12977: 2 | C12977: P101-1 | D12977: ULS-NBR-3 | E12977: Combination | F12977: Bottom | G12977: -296.7021 | H12977: 73.5492 | I12977: 9.7291 | J12977: -6.4722 | K12977: -1.6321 | L12977: -152.3206
A12978: Story1 | B12978: 2 | C12978: P101-1 | D12978: ULS-NBR-3 | E12978: Combination | F12978: Top | G12978: -769.7666 | H12978: 11.653 | I12978: 6.1916 | J12978: -22.5063 | K12978: -12.7783 | L12978: -72.6776
A12979: Story1 | B12979: 2 | C12979: P101-1 | D12979: ULS-NBR-3 | E12979: Combination | F12979: Bottom | G12979: -687.7989 | H12979: 38.1674 | I12979: 6.4884 | J12979: -11.2122 | K12979: -4.1018 | L12979: -191.1321
... A13037: Story1 | B13037: 2 | C13037: P101-5 | D13037: ULS-NBR-4 | E13037: Combination | F13037: Bottom | G13037: -1055.1742 | H13037: -92.6853 | I13037: -24.2894 | J13037: 23.8668 | K13037: -198.1685 | L13037: -188.7036
A13038: Story1 | B13038: =VLOOKUP(A13038,Plan1!$A$3:$B$65,2,FALSE) -> 1 | C13038: P8-1 | D13038: ULS-NBR-1 | E13038: Combination | F13038: Top | G13038: -3816.1306 | H13038: 956.5938 | I13038: 66.5796 | J13038: -54.0032 | K13038: 41.5039 | L13038: 7517.0703
A13039: Story1 | B13039: =VLOOKUP(A13039,Plan1!$A$3:$B$65,2,FALSE) -> 1 | C13039: P8-1 | D13039: ULS-NBR-1 | E13039: Combination | F13039: Bottom | G13039: -3719.9317 | H13039: 1046.8211 | I13039: 92.492 | J13039: 72.3279 | K13039: 145.5611 | L13039: 10459.041
A13040: Story1 | B13040: =VLOOKUP(A13040,Plan1!$A$3:$B$65,2,FALSE) -> 1 | C13040: P8-1 | D13040: ULS-NBR-1 | E13040: Combination | F13040: Top | G13040: -5443.0643 | H13040: 477.1843 | I13040: -2.9095 | J13040: -115.7827 | K13040: 28.422 | L13040: 3582.914
A13041: Story1 | B13041: =VLOOKUP(A13041,Plan1!$A$3:$B$65,2,FALSE) -> 1 | C13041: P8-1 | D13041: ULS-NBR-1 | E13041: Combination | F13041: Bottom | G13041: -5242.5686 | H13041: 543.3017 | I13041: 21.5692 | J13041: 31.1917 | K13041: 59.4896 | L13041: 5621.8448
A13042: Story1 | B13042: =VLOOKUP(A13042,Plan1!$A$3:$B$65,2,FALSE) -> 1 | C13042: P8-1 | D13042: ULS-NBR-2 | E13042: Combination | F13042: Top | G13042: -2247.7935 | H13042: 709.9851 | I13042: 67.575 | J13042: -21.0084 | K13042: 20.0531 | L13042: 5585.6926
A13043: Story1 | B13043: =VLOOKUP(A13043,Plan1!$A$3:$B$65,2,FALSE) -> 1 | C13043: P8-1 | D13043: ULS-NBR-2 | E13043: Combination | F13043: Bottom | G13043: -2205.1548 | H13043: 774.3599 | I13043: 83.529 | J13043: 59.4246 | K13043: 115.0466 | L13043: 7692.4002
A13044: Story1 | B13044: =VLOOKUP(A13044,Plan1!$A$3:$B$65,2,FALSE) -> 1 | C13044: P8-1 | D13044: ULS-NBR-2 | E13044: Combination | F13044: Top | G13044: -3874.7272 | H13044: 230.5756 | I13044: -1.9141 | J13044: -82.7878 | K13044: 6.9712 | L13044: 1651.5363
A13045: Story1 | B13045: =VLOOKUP(A13045,Plan1!$A$3:$B$65,2,FALSE) -> 1 | C13045: P8-1 | D13045: ULS-NBR-2 | E13045: Combination | F13045: Bottom | G13045: -3727.7917 | H13045: 270.8404 | I13045: 12.6063 | J13045: 18.2885 | K13045: 28.9752 | L13045: 2855.2043
A13046: Story1 | B13046: =VLOOKUP(A13046,Plan1!$A$3:$B$65,2,FALSE) -> 1 | C13046: P8-1 | D13046: ULS-NBR-3 | E13046: Combination | F13046: Top | G13046: -4485.3503 | H13046: 919.2085 | I13046: 38.5543 | J13046: -78.5948 | K13046: 54.9335 | L13046: 7214.1709
A13047: Story1 | B13047: =VLOOKUP(A13047,Plan1!$A$3:$B$65,2,FALSE) -> 1 | C13047: P8-1 | D13047: ULS-NBR-3 | E13047: Combination | F13047: Bottom | G13047: -4352.6466 | H13047: 1009.5384 | I13047: 68.0433 | J13047: 61.4612 | K13047: 130.0569 | L13047: 10148.721
A13048: Story1 | B13048: =VLOOKUP(A13048,Plan1!$A$3:$B$65,2,FALSE) -> 1 | C13048: P8-1 | D13048: ULS-NBR-3 | E13048: Combination | F13048: Top | G13048: -5461.5106 | H13048: 631.5628 | I13048: -3.1392 | J13048: -115.6624 | K13048: 47.0843 | L13048: 4853.6772
...

Sheet Pier Forces
A1: TABLE: Pier Forces
A2: Story | B2: Story | C2: Pier | D2: Output Case | E2: Case Type | F2: Location | G2: P | H2: V2 | I2: V3 | J2: T | K2: M2 | L2: M3
A3: ETABS | B3: TQS | G3: tonf | H3: tonf | I3: tonf | J3: tonf-m | K3: tonf-m | L3: tonf-m
A4: Story50-AC | B4: =VLOOKUP(A4,Plan1!$A$3:$B$65,2,FALSE) -> 52 | C4: P8 | D4: ULS-NBR-1 | E4: Combination | F4: Top | G4: -41.0691 | H4: -27.7677 | I4: 19.2086 | J4: 15.4311 | K4: 14.0292 | L4: 6.2622
A5: Story50-AC | B5: =VLOOKUP(A5,Plan1!$A$3:$B$65,2,FALSE) -> 52 | C5: P8 | D5: ULS-NBR-1 | E5: Combination | F5: Bottom | G5: -124.6199 | H5: -34.3019 | I5: 19.0699 | J5: 42.7729 | K5: 140.9402 | L5: -155.4308
A6: Story50-AC | B6: =VLOOKUP(A6,Plan1!$A$3:$B$65,2,FALSE) -> 52 | C6: P8 | D6: ULS-NBR-1 | E6: Combination | F6: Top | G6: -51.0905 | H6: -42.3008 | I6: -15.6579 | J6: -48.8645 | K6: -19.9574 | L6: -46.3087
A7: Story50-AC | B7: =VLOOKUP(A7,Plan1!$A$3:$B$65,2,FALSE) -> 52 | C7: P8 | D7: ULS-NBR-1 | E7: Combination | F7: Bottom | G7: -177.1007 | H7: -67.9104 | I7: -15.2701 | J7: -101.8815 | K7: -145.4754 | L7: -497.7709
A8: Story50-AC | B8: =VLOOKUP(A8,Plan1!$A$3:$B$65,2,FALSE) -> 52 | C8: P8 | D8: ULS-NBR-2 | E8: Combination | F8: Top | G8: -24.4358 | H8: -14.2249 | I8: 19.2637 | J8: 18.5553 | K8: 15.7775 | L8: 15.3872
A9: Story50-AC | B9: =VLOOKUP(A9,Plan1!$A$3:$B$65,2,FALSE) -> 52 | C9: P8 | D9: ULS-NBR-2 | E9: Combination | F9: Bottom | G9: -74.0806 | H9: -14.6061 | I9: 19.0912 | J9: 51.8026 | K9: 147.5024 | L9: -25.1143
A10: Story50-AC | B10: =VLOOKUP(A10,Plan1!$A$3:$B$65,2,FALSE) -> 52 | C10: P8 | D10: ULS-NBR-2 | E10: Combination | F10: Top | G10: -34.4572 | H10: -28.758 | I10: -15.6028 | J10: -45.7403 | K10: -18.209 | L10: -37.1837
A11: Story50-AC | B11: =VLOOKUP(A11,Plan1!$A$3:$B$65,2,FALSE) -> 52 | C11: P8 | D11: ULS-NBR-2 | E11: Combination | F11: Bottom | G11: -126.5614 | H11: -48.2146 | I11: -15.2489 | J11: -92.8518 | K11: -138.9132 | L11: -367.4544
A12: Story50-AC | B12: =VLOOKUP(A12,Plan1!$A$3:$B$65,2,FALSE) -> 52 | C12: P8 | D12: ULS-NBR-3 | E12: Combination | F12: Top | G12: -47.9281 | H12: -35.6206 | I12: 11.448 | J12: 4.8848 | K12: 5.9698 | L12: -9.0177
A13: Story50-AC | B13: =VLOOKUP(A13,Plan1!$A$3:$B$65,2,FALSE) -> 52 | C13: P8 | D13: ULS-NBR-3 | E13: Combination | F13: Bottom | G13: -145.527 | H13: -48.1552 | I13: 11.4122 | J13: 13.0221 | K13: 75.3771 | L13: -275.7016
A14: Story50-AC | B14: =VLOOKUP(A14,Plan1!$A$3:$B$65,2,FALSE) -> 52 | C14: P8 | D14: ULS-NBR-3 | E14: Combination | F14: Top | G14: -53.9409 | H14: -44.3404 | I14: -9.4719 | J14: -33.6926 | K14: -14.4221 | L14: -40.5602
A15: Story50-AC | B15: =VLOOKUP(A15,Plan1!$A$3:$B$65,2,FALSE) -> 52 | C15: P8 | D15: ULS-NBR-3 | E15: Combination | F15: Bottom | G15: -177.0155 | H15: -68.3203 | I15: -9.1918 | J15: -73.7705 | K15: -96.4723 | L15: -481.1057
... A11819: Story1 | B11819: =VLOOKUP(A11819,Plan1!$A$3:$B$65,2,FALSE) -> 1 | C11819: P8 | D11819: ULS-NBR-4 | E11819: Combination | F11819: Bottom | G11819: -11932.92 | H11819: 838.7915 | I11819: 522.1525 | J11819: -369.3365 | K11819: 10138.393 | L11819: 8146.0364
A11820: Story1 | B11820: 3 | C11820: P9 | D11820: ULS-NBR-1 | E11820: Combination | F11820: Top | G11820: -770.2216 | H11820: 10.2472 | I11820: -0.9323 | J11820: 0.6051 | K11820: 5.6643 | L11820: 192.6015
A11821: Story1 | B11821: 3 | C11821: P9 | D11821: ULS-NBR-1 | E11821: Combination | F11821: Bottom | G11821: -773.0429 | H11821: 10.2471 | I11821: -0.9323 | J11821: 0.6062 | K11821: 2.1144 | L11821: 206.7346
A11822: Story1 | B11822: 3 | C11822: P9 | D11822: ULS-NBR-1 | E11822: Combination | F11822: Top | G11822: -1372.2621 | H11822: -11.2667 | I11822: -10.6319 | J11822: -1.3939 | K11822: -0.7965 | L11822: 17.5388
A11823: Story1 | B11823: 3 | C11823: P9 | D11823: ULS-NBR-1 | E11823: Combination | F11823: Bottom | G11823: -1375.0834 | H11823: -11.2667 | I11823: -10.6319 | J11823: -1.3982 | K11823: -11.1043 | L11823: 2.6366
A11824: Story1 | B11824: 3 | C11824: P9 | D11824: ULS-NBR-2 | E11824: Combination | F11824: Top | G11824: -418.5609 | H11824: 10.2257 | I11824: 0.8654 | J11824: 0.7496 | K11824: 4.8074 | L11824: 155.5364
A11825: Story1 | B11825: 3 | C11825: P9 | D11825: ULS-NBR-2 | E11825: Combination | F11825: Bottom | G11825: -420.5761 | H11825: 10.2257 | I11825: 0.8654 | J11825: 0.7512 | K11825: 3.6322 | L11825: 169.5373
A11826: Story1 | B11826: 3 | C11826: P9 | D11826: ULS-NBR-2 | E11826: Combination | F11826: Top | G11826: -1020.6014 | H11826: -11.2881 | I11826: -8.8342 | J11826: -1.2495 | K11826: -1.6534 | L11826: -19.5263
A11827: Story1 | B11827: 3 | C11827: P9 | D11827: ULS-NBR-2 | E11827: Combination | F11827: Bottom | G11827: -1022.6165 | H11827: -11.2882 | I11827: -8.8342 | J11827: -1.2532 | K11827: -9.5865 | L11827: -34.5607
A11828: Story1 | B11828: 3 | C11828: P9 | D11828: ULS-NBR-3 | E11828: Combination | F11828: Top | G11828: -954.458 | H11828: 6.1783 | I11828: -3.0762 | J11828: 0.1608 | K11828: 4.5982 | L11828: 167.4521
A11829: Story1 | B11829: 3 | C11829: P9 | D11829: ULS-NBR-3 | E11829: Combination | F11829: Bottom | G11829: -957.2793 | H11829: 6.1783 | I11829: -3.0762 | J11829: 0.1607 | K11829: -0.8563 | L11829: 176.117
A11830: Story1 | B11830: 3 | C11830: P9 | D11830: ULS-NBR-3 | E11830: Combination | F11830: Top | G11830: -1315.6823 | H11830: -6.73 | I11830: -8.896 | J11830: -1.0387 | K11830: 0.7218 | L11830: 62.4145
A11831: Story1 | B11831: 3 | C11831: P9 | D11831: ULS-NBR-3 | E11831: Combination | F11831: Bottom | G11831: -1318.5036 | H11831: -6.73 | I11831: -8.896 | J11831: -1.042 | K11831: -8.7875 | L11831: 53.6582
... A11833: Story1 | B11833: 3 | C11833: P9 | D11833: ULS-NBR-4 | E11833: Combination | F11833: Bottom | G11833: -1129.0663 | H11833: 0.2869 | I11833: -5.7586 | J11833: -0.408 | K11833: -4.645 | L11833: 118.9243
A11834: Story1 | B11834: =VLOOKUP(A11834,Plan1!$A$3:$B$65,2,FALSE) -> 1 | C11834: P10 | D11834: ULS-NBR-1 | E11834: Combination | F11834: Top | G11834: -2676.6032 | H11834: -150.2602 | I11834: -266.815 | J11834: 435.3873 | K11834: -194.8277 | L11834: -302.5769
A11835: Story1 | B11835: =VLOOKUP(A11835,Plan1!$A$3:$B$65,2,FALSE) -> 1 | C11835: P10 | D11835: ULS-NBR-1 | E11835: Combination | F11835: Bottom | G11835: -2686.3082 | H11835: -150.2613 | I11835: -266.8151 | J11835: 435.4401 | K11835: -541.7392 | L11835: -510.2342
A11836: Story1 | B11836: =VLOOKUP(A11836,Plan1!$A$3:$B$65,2,FALSE) -> 1 | C11836: P10 | D11836: ULS-NBR-1 | E11836: Combination | F11836: Top | G11836: -3754.4585 | H11836: -333.5871 | I11836: -346.6942 | J11836: 235.0528 | K11836: -785.9773 | L11836: -1062.3173
A11837: Story1 | B11837: =VLOOKUP(A11837,Plan1!$A$3:$B$65,2,FALSE) -> 1 | C11837: P10 | D11837: ULS-NBR-1 | E11837: Combination | F11837: Bottom | G11837: -3764.1635 | H11837: -333.5882 | I11837: -346.6943 | J11837: 235.0844 | K11837: -1237.7669 | L11837: -1482.6017
A11838: Story1 | B11838: =VLOOKUP(A11838,Plan1!$A$3:$B$65,2,FALSE) -> 1 | C11838: P10 | D11838: ULS-NBR-2 | E11838: Combination | F11838: Top | G11838: -1620.7439 | H11838: -70.9076 | I11838: -166.0126 | J11838: 322.365 | K11838: -24.1327 | L11838: -74.3288
A11839: Story1 | B11839: =VLOOKUP(A11839,Plan1!$A$3:$B$65,2,FALSE) -> 1 | C11839: P10 | D11839: ULS-NBR-2 | E11839: Combination | F11839: Bottom | G11839: -1627.6761 | H11839: -70.9084 | I11839: -166.0126 | J11839: 322.4041 | K11839: -239.7736 | L11839: -178.5169
A11840: Story1 | B11840: =VLOOKUP(A11840,Plan1!$A$3:$B$65,2,FALSE) -> 1 | C11840: P10 | D11840: ULS-NBR-2 | E11840: Combination | F11840: Top | G11840: -2698.5992 | H11840: -254.2345 | I11840: -245.8918 | J11840: 122.0305 | K11840: -615.2823 | L11840: -834.0692
A11841: Story1 | B11841: =VLOOKUP(A11841,Plan1!$A$3:$B$65,2,FALSE) -> 1 | C11841: P10 | D11841: ULS-NBR-2 | E11841: Combination | F11841: Bottom | G11841: -2705.5313 | H11841: -254.2353 | I11841: -245.8918 | J11841: 122.0484 | K11841: -935.8013 | L11841: -1150.8843
A11842: Story1 | B11842: =VLOOKUP(A11842,Plan1!$A$3:$B$65,2,FALSE) -> 1 | C11842: P10 | D11842: ULS-NBR-3 | E11842: Combination | F11842: Top | G11842: -3084.1649 | H11842: -201.2499 | I11842: -301.2124 | J11842: 419.4636 | K11842: -355.8696 | L11842: -501.0934
A11843: Story1 | B11843: =VLOOKUP(A11843,Plan1!$A$3:$B$65,2,FALSE) -> 1 | C11843: P10 | D11843: ULS-NBR-3 | E11843: Combination | F11843: Bottom | G11843: -3093.87 | H11843: -201.251 | I11843: -301.2125 | J11843: 419.5146 | K11843: -747.7954 | L11843: -770.5448
A11844: Story1 | B11844: =VLOOKUP(A11844,Plan1!$A$3:$B$65,2,FALSE) -> 1 | C11844: P10 | D11844: ULS-NBR-3 | E11844: Combination | F11844: Top | G11844: -3730.8781 | H11844: -311.246 | I11844: -349.1399 | J11844: 299.2629 | K11844: -710.5594 | L11844: -956.9377
...
